Watching for file changes with StatReloader
"GET /admin HTTP/1.1" 301 0
"GET /admin/ HTTP/1.1" 302 0
"GET /admin/login/?next=/admin/ HTTP/1.1" 200 4158
"GET /static/admin/css/dark_mode.css HTTP/1.1" 200 2682
"GET /static/admin/js/theme.js HTTP/1.1" 200 1943
"GET /static/admin/js/nav_sidebar.js HTTP/1.1" 200 3063
"GET /static/admin/css/nav_sidebar.css HTTP/1.1" 200 2810
"GET /static/admin/css/login.css HTTP/1.1" 200 958
"GET /static/admin/css/base.css HTTP/1.1" 200 21544
"GET /static/admin/css/responsive.css HTTP/1.1" 200 17905
Not Found: /favicon.ico
Not Found: /apple-touch-icon-precomposed.png
"GET /apple-touch-icon-precomposed.png HTTP/1.1" 404 2861
"GET /favicon.ico HTTP/1.1" 404 2798
Not Found: /apple-touch-icon.png
"GET /apple-touch-icon.png HTTP/1.1" 404 2825
"POST /admin/login/?next=/admin/ HTTP/1.1" 302 0
"GET /admin/ HTTP/1.1" 200 7603
"GET /static/admin/css/dashboard.css HTTP/1.1" 200 441
"GET /static/admin/img/icon-changelink.svg HTTP/1.1" 200 380
"GET /static/admin/img/icon-addlink.svg HTTP/1.1" 200 331
"GET /admin/ HTTP/1.1" 200 7603
Not Found: /api/vacancies/
"GET /api/vacancies/ HTTP/1.1" 404 2807
Not Found: /api/vacancies/
"GET /api/vacancies/ HTTP/1.1" 404 2807
Method Not Allowed: /api/users/register/
"GET /api/users/register/ HTTP/1.1" 405 8457
"GET /static/rest_framework/css/prettify.css HTTP/1.1" 200 817
"GET /static/rest_framework/css/default.css HTTP/1.1" 200 1152
"GET /static/rest_framework/css/bootstrap-tweaks.css HTTP/1.1" 200 3426
"GET /static/rest_framework/js/ajax-form.js HTTP/1.1" 200 3796
"GET /static/rest_framework/js/csrf.js HTTP/1.1" 200 1793
"GET /static/rest_framework/css/bootstrap.min.css HTTP/1.1" 200 121457
"GET /static/rest_framework/js/default.js HTTP/1.1" 200 1268
"GET /static/rest_framework/js/prettify-min.js HTTP/1.1" 200 13632
"GET /static/rest_framework/js/jquery-3.7.1.min.js HTTP/1.1" 200 87533
"GET /static/rest_framework/js/bootstrap.min.js HTTP/1.1" 200 39680
"GET /static/rest_framework/js/load-ajax-form.js HTTP/1.1" 200 59
"GET /static/rest_framework/img/grid.png HTTP/1.1" 200 1458
Bad Request: /api/users/register/
"POST /api/users/register/ HTTP/1.1" 400 8595
"POST /api/users/register/ HTTP/1.1" 200 8721
Method Not Allowed: /api/users/register/
"GET /api/users/register/ HTTP/1.1" 405 8457
Method Not Allowed: /api/users/login/
"GET /api/users/login/ HTTP/1.1" 405 7639
Bad Request: /api/users/register/
"POST /api/users/register/ HTTP/1.1" 400 8611
Bad Request: /api/users/login/
"POST /api/users/login/ HTTP/1.1" 400 7744
Unauthorized: /api/users/login/
"POST /api/users/login/ HTTP/1.1" 401 7579
Method Not Allowed: /api/users/register/
"GET /api/users/register/ HTTP/1.1" 405 8457
/Users/nursultantolegen/sales_trading_app/users/permissions.py changed, reloading.
Watching for file changes with StatReloader
Method Not Allowed: /api/users/token/refresh/
"GET /api/users/token/refresh/ HTTP/1.1" 405 7342
"OPTIONS /api/users/token/refresh/ HTTP/1.1" 200 8291
"OPTIONS /api/users/token/refresh/ HTTP/1.1" 200 8291
Method Not Allowed: /api/users/token/refresh/
"GET /api/users/token/refresh/ HTTP/1.1" 405 7342
Unauthorized: /api/users/users/
"GET /api/users/users/ HTTP/1.1" 401 5075
Method Not Allowed: /api/users/token/refresh/
"GET /api/users/token/refresh/ HTTP/1.1" 405 7342
Not Found: /api/users/
"GET /api/users/ HTTP/1.1" 404 3811
Unauthorized: /api/users/trader-dashboard/
"GET /api/users/trader-dashboard/ HTTP/1.1" 401 5172
Method Not Allowed: /api/users/token/refresh/
"GET /api/users/token/refresh/ HTTP/1.1" 405 7342
Method Not Allowed: /api/users/register/
"GET /api/users/register/ HTTP/1.1" 405 8457
"POST /api/users/register/ HTTP/1.1" 200 8856
Method Not Allowed: /api/users/register/
"GET /api/users/register/ HTTP/1.1" 405 8457
Unauthorized: /api/users/trader-dashboard/
"GET /api/users/trader-dashboard/ HTTP/1.1" 401 5172
Method Not Allowed: /api/users/token/refresh/
"GET /api/users/token/refresh/ HTTP/1.1" 405 7342
Method Not Allowed: /api/users/register/
"GET /api/users/register/ HTTP/1.1" 405 8457
Method Not Allowed: /api/users/login/
"GET /api/users/login/ HTTP/1.1" 405 7639
Method Not Allowed: /api/users/register/
"GET /api/users/register/ HTTP/1.1" 405 8457
"GET /admin/ HTTP/1.1" 200 7603
Not Found: /
"GET / HTTP/1.1" 404 2747
"GET /admin/ HTTP/1.1" 200 7603
Method Not Allowed: /api/users/register/
"GET /api/users/register/ HTTP/1.1" 405 8457
Not Found: /api/products/1
"GET /api/products/1 HTTP/1.1" 404 3494
Not Found: /api/products/1
"GET /api/products/1 HTTP/1.1" 404 3494
Not Found: /api/products/
"GET /api/products/ HTTP/1.1" 404 3491
"GET /api/products/categories/ HTTP/1.1" 200 5208
"GET /api/products/categories/ HTTP/1.1" 200 5208
"GET /api/products/categories/ HTTP/1.1" 200 5208
"GET /api/products/categories/?format=json HTTP/1.1" 200 2
Internal Server Error: /api/products/products/
Traceback (most recent call last):
  File "/Library/Frameworks/Python.framework/Versions/3.10/lib/python3.10/site-packages/django/core/handlers/exception.py", line 55, in inner
    response = get_response(request)
  File "/Library/Frameworks/Python.framework/Versions/3.10/lib/python3.10/site-packages/django/core/handlers/base.py", line 197, in _get_response
    response = wrapped_callback(request, *callback_args, **callback_kwargs)
  File "/Library/Frameworks/Python.framework/Versions/3.10/lib/python3.10/site-packages/django/views/decorators/csrf.py", line 65, in _view_wrapper
    return view_func(request, *args, **kwargs)
  File "/Library/Frameworks/Python.framework/Versions/3.10/lib/python3.10/site-packages/rest_framework/viewsets.py", line 116, in view
    handler = getattr(self, action)
AttributeError: 'ProductViewSet' object has no attribute 'create'
"GET /api/products/products/ HTTP/1.1" 500 67416
Internal Server Error: /api/products/products/
Traceback (most recent call last):
  File "/Library/Frameworks/Python.framework/Versions/3.10/lib/python3.10/site-packages/django/core/handlers/exception.py", line 55, in inner
    response = get_response(request)
  File "/Library/Frameworks/Python.framework/Versions/3.10/lib/python3.10/site-packages/django/core/handlers/base.py", line 197, in _get_response
    response = wrapped_callback(request, *callback_args, **callback_kwargs)
  File "/Library/Frameworks/Python.framework/Versions/3.10/lib/python3.10/site-packages/django/views/decorators/csrf.py", line 65, in _view_wrapper
    return view_func(request, *args, **kwargs)
  File "/Library/Frameworks/Python.framework/Versions/3.10/lib/python3.10/site-packages/rest_framework/viewsets.py", line 116, in view
    handler = getattr(self, action)
AttributeError: 'ProductViewSet' object has no attribute 'create'
"GET /api/products/products/ HTTP/1.1" 500 67416
"GET /api/products/categories/ HTTP/1.1" 200 5208
"GET /api/products/categories/ HTTP/1.1" 200 5208
Internal Server Error: /api/products/products/
Traceback (most recent call last):
  File "/Library/Frameworks/Python.framework/Versions/3.10/lib/python3.10/site-packages/django/core/handlers/exception.py", line 55, in inner
    response = get_response(request)
  File "/Library/Frameworks/Python.framework/Versions/3.10/lib/python3.10/site-packages/django/core/handlers/base.py", line 197, in _get_response
    response = wrapped_callback(request, *callback_args, **callback_kwargs)
  File "/Library/Frameworks/Python.framework/Versions/3.10/lib/python3.10/site-packages/django/views/decorators/csrf.py", line 65, in _view_wrapper
    return view_func(request, *args, **kwargs)
  File "/Library/Frameworks/Python.framework/Versions/3.10/lib/python3.10/site-packages/rest_framework/viewsets.py", line 116, in view
    handler = getattr(self, action)
AttributeError: 'ProductViewSet' object has no attribute 'create'
"GET /api/products/products/ HTTP/1.1" 500 67416
Not Found: /api/products/
"GET /api/products/ HTTP/1.1" 404 3491
Internal Server Error: /api/products/products/
Traceback (most recent call last):
  File "/Library/Frameworks/Python.framework/Versions/3.10/lib/python3.10/site-packages/django/core/handlers/exception.py", line 55, in inner
    response = get_response(request)
  File "/Library/Frameworks/Python.framework/Versions/3.10/lib/python3.10/site-packages/django/core/handlers/base.py", line 197, in _get_response
    response = wrapped_callback(request, *callback_args, **callback_kwargs)
  File "/Library/Frameworks/Python.framework/Versions/3.10/lib/python3.10/site-packages/django/views/decorators/csrf.py", line 65, in _view_wrapper
    return view_func(request, *args, **kwargs)
  File "/Library/Frameworks/Python.framework/Versions/3.10/lib/python3.10/site-packages/rest_framework/viewsets.py", line 116, in view
    handler = getattr(self, action)
AttributeError: 'ProductViewSet' object has no attribute 'create'
"GET /api/products/products/ HTTP/1.1" 500 67416
/Users/nursultantolegen/sales_trading_app/products/urls.py changed, reloading.
Watching for file changes with StatReloader
Internal Server Error: /api/products/product/
Traceback (most recent call last):
  File "/Library/Frameworks/Python.framework/Versions/3.10/lib/python3.10/site-packages/django/core/handlers/exception.py", line 55, in inner
    response = get_response(request)
  File "/Library/Frameworks/Python.framework/Versions/3.10/lib/python3.10/site-packages/django/core/handlers/base.py", line 197, in _get_response
    response = wrapped_callback(request, *callback_args, **callback_kwargs)
  File "/Library/Frameworks/Python.framework/Versions/3.10/lib/python3.10/site-packages/django/views/decorators/csrf.py", line 65, in _view_wrapper
    return view_func(request, *args, **kwargs)
  File "/Library/Frameworks/Python.framework/Versions/3.10/lib/python3.10/site-packages/rest_framework/viewsets.py", line 116, in view
    handler = getattr(self, action)
AttributeError: 'ProductViewSet' object has no attribute 'create'
"GET /api/products/product/ HTTP/1.1" 500 67405
Not Found: /api/products/products/
"GET /api/products/products/ HTTP/1.1" 404 3517
"GET /api/products/categories/?format=json HTTP/1.1" 200 2
"GET /api/products/categories/ HTTP/1.1" 200 5208
"GET /api/products/categories/ HTTP/1.1" 200 5208
"GET /api/products/categories/ HTTP/1.1" 200 5208
Internal Server Error: /api/products/product/
Traceback (most recent call last):
  File "/Library/Frameworks/Python.framework/Versions/3.10/lib/python3.10/site-packages/django/core/handlers/exception.py", line 55, in inner
    response = get_response(request)
  File "/Library/Frameworks/Python.framework/Versions/3.10/lib/python3.10/site-packages/django/core/handlers/base.py", line 197, in _get_response
    response = wrapped_callback(request, *callback_args, **callback_kwargs)
  File "/Library/Frameworks/Python.framework/Versions/3.10/lib/python3.10/site-packages/django/views/decorators/csrf.py", line 65, in _view_wrapper
    return view_func(request, *args, **kwargs)
  File "/Library/Frameworks/Python.framework/Versions/3.10/lib/python3.10/site-packages/rest_framework/viewsets.py", line 116, in view
    handler = getattr(self, action)
AttributeError: 'ProductViewSet' object has no attribute 'create'
"GET /api/products/product/ HTTP/1.1" 500 67405
Not Found: /
"GET / HTTP/1.1" 404 2747
"GET /admin/ HTTP/1.1" 200 7603
Method Not Allowed: /api/users/register/
"GET /api/users/register/ HTTP/1.1" 405 8457
Not Found: /api/trading/order/
"GET /api/trading/order/ HTTP/1.1" 404 3283
Unauthorized: /api/trading/orders/create/
"GET /api/trading/orders/create/ HTTP/1.1" 401 3904
Method Not Allowed: /api/users/register/
"GET /api/users/register/ HTTP/1.1" 405 8457
"OPTIONS /api/users/register/ HTTP/1.1" 200 11090
Unauthorized: /api/trading/orders/create/
"GET /api/trading/orders/create/ HTTP/1.1" 401 3904
Method Not Allowed: /api/users/register/
"GET /api/users/register/ HTTP/1.1" 405 8457
Method Not Allowed: /api/users/register/
"GET /api/users/register/ HTTP/1.1" 405 8457
Method Not Allowed: /api/users/register/
"GET /api/users/register/ HTTP/1.1" 405 8457
Not Found: /api/admin
"GET /api/admin HTTP/1.1" 404 2792
"GET /admin/ HTTP/1.1" 200 7603
"GET /admin/auth/group/add/ HTTP/1.1" 200 14548
"GET /static/admin/js/jquery.init.js HTTP/1.1" 200 347
"GET /static/admin/css/forms.css HTTP/1.1" 200 9090
"GET /static/admin/js/core.js HTTP/1.1" 200 6208
"GET /static/admin/js/admin/RelatedObjectLookups.js HTTP/1.1" 200 9042
"GET /static/admin/js/SelectBox.js HTTP/1.1" 200 4530
"GET /static/admin/js/actions.js HTTP/1.1" 200 8067
"GET /static/admin/js/prepopulate.js HTTP/1.1" 200 1531
"GET /static/admin/js/SelectFilter2.js HTTP/1.1" 200 15492
"GET /static/admin/js/urlify.js HTTP/1.1" 200 7887
"GET /static/admin/js/prepopulate_init.js HTTP/1.1" 200 586
"GET /static/admin/css/widgets.css HTTP/1.1" 200 11800
"GET /static/admin/js/change_form.js HTTP/1.1" 200 606
"GET /admin/jsi18n/ HTTP/1.1" 200 3342
"GET /static/admin/js/vendor/jquery/jquery.js HTTP/1.1" 200 285314
"GET /static/admin/js/vendor/xregexp/xregexp.js HTTP/1.1" 200 325171
"GET /static/admin/img/search.svg HTTP/1.1" 200 458
"GET /static/admin/img/selector-icons.svg HTTP/1.1" 200 3291
"GET /admin/sales/salesorder/add/ HTTP/1.1" 200 10956
"GET /admin/jsi18n/ HTTP/1.1" 200 3342
"GET /admin/trading/order/ HTTP/1.1" 200 10281
"GET /static/admin/css/changelists.css HTTP/1.1" 200 6811
"GET /static/admin/js/filters.js HTTP/1.1" 200 978
"GET /admin/jsi18n/ HTTP/1.1" 200 3342
"GET /static/admin/img/tooltag-add.svg HTTP/1.1" 200 331
"GET /static/admin/img/icon-viewlink.svg HTTP/1.1" 200 581
"GET /admin/auth/group/ HTTP/1.1" 200 8897
"GET /admin/jsi18n/ HTTP/1.1" 200 3342
"GET /admin/ HTTP/1.1" 200 7603
Not Found: /
"GET / HTTP/1.1" 404 2747
"GET /admin/ HTTP/1.1" 200 7603
Method Not Allowed: /api/users/register/
"GET /api/users/register/ HTTP/1.1" 405 8457
Method Not Allowed: /api/users/register/
"GET /api/users/register/ HTTP/1.1" 405 8457
Not Found: /api/products/products/
"GET /api/products/products/ HTTP/1.1" 404 3517
Internal Server Error: /api/products/product/
Traceback (most recent call last):
  File "/Library/Frameworks/Python.framework/Versions/3.10/lib/python3.10/site-packages/django/core/handlers/exception.py", line 55, in inner
    response = get_response(request)
  File "/Library/Frameworks/Python.framework/Versions/3.10/lib/python3.10/site-packages/django/core/handlers/base.py", line 197, in _get_response
    response = wrapped_callback(request, *callback_args, **callback_kwargs)
  File "/Library/Frameworks/Python.framework/Versions/3.10/lib/python3.10/site-packages/django/views/decorators/csrf.py", line 65, in _view_wrapper
    return view_func(request, *args, **kwargs)
  File "/Library/Frameworks/Python.framework/Versions/3.10/lib/python3.10/site-packages/rest_framework/viewsets.py", line 116, in view
    handler = getattr(self, action)
AttributeError: 'ProductViewSet' object has no attribute 'create'
"GET /api/products/product/ HTTP/1.1" 500 67405
"GET /api/products/categories/?format=json HTTP/1.1" 200 2
"GET /api/products/categories/?format=json HTTP/1.1" 200 2
"GET /api/products/categories/ HTTP/1.1" 200 5208
Watching for file changes with StatReloader
Not Found: /
"GET / HTTP/1.1" 404 2747
Not Found: /
"GET / HTTP/1.1" 404 2747
Method Not Allowed: /api/users/register/
"GET /api/users/register/ HTTP/1.1" 405 8457
"GET /api/products/categories/?format=json HTTP/1.1" 200 2
"GET /api/products/categories/?format=json HTTP/1.1" 200 2
Internal Server Error: /api/products/product/
Traceback (most recent call last):
  File "/Library/Frameworks/Python.framework/Versions/3.10/lib/python3.10/site-packages/redis/connection.py", line 357, in connect
    sock = self.retry.call_with_retry(
  File "/Library/Frameworks/Python.framework/Versions/3.10/lib/python3.10/site-packages/redis/retry.py", line 62, in call_with_retry
    return do()
  File "/Library/Frameworks/Python.framework/Versions/3.10/lib/python3.10/site-packages/redis/connection.py", line 358, in <lambda>
    lambda: self._connect(), lambda error: self.disconnect(error)
  File "/Library/Frameworks/Python.framework/Versions/3.10/lib/python3.10/site-packages/redis/connection.py", line 730, in _connect
    raise err
  File "/Library/Frameworks/Python.framework/Versions/3.10/lib/python3.10/site-packages/redis/connection.py", line 718, in _connect
    sock.connect(socket_address)
ConnectionRefusedError: [Errno 61] Connection refused

During handling of the above exception, another exception occurred:

Traceback (most recent call last):
  File "/Library/Frameworks/Python.framework/Versions/3.10/lib/python3.10/site-packages/django/core/handlers/exception.py", line 55, in inner
    response = get_response(request)
  File "/Library/Frameworks/Python.framework/Versions/3.10/lib/python3.10/site-packages/django/core/handlers/base.py", line 197, in _get_response
    response = wrapped_callback(request, *callback_args, **callback_kwargs)
  File "/Library/Frameworks/Python.framework/Versions/3.10/lib/python3.10/site-packages/django/views/decorators/csrf.py", line 65, in _view_wrapper
    return view_func(request, *args, **kwargs)
  File "/Library/Frameworks/Python.framework/Versions/3.10/lib/python3.10/site-packages/rest_framework/viewsets.py", line 124, in view
    return self.dispatch(request, *args, **kwargs)
  File "/Library/Frameworks/Python.framework/Versions/3.10/lib/python3.10/site-packages/rest_framework/views.py", line 509, in dispatch
    response = self.handle_exception(exc)
  File "/Library/Frameworks/Python.framework/Versions/3.10/lib/python3.10/site-packages/rest_framework/views.py", line 469, in handle_exception
    self.raise_uncaught_exception(exc)
  File "/Library/Frameworks/Python.framework/Versions/3.10/lib/python3.10/site-packages/rest_framework/views.py", line 480, in raise_uncaught_exception
    raise exc
  File "/Library/Frameworks/Python.framework/Versions/3.10/lib/python3.10/site-packages/rest_framework/views.py", line 506, in dispatch
    response = handler(request, *args, **kwargs)
  File "/Users/nursultantolegen/sales_trading_app/products/views.py", line 17, in list
    cached_data = cache.get(cache_key)
  File "/Library/Frameworks/Python.framework/Versions/3.10/lib/python3.10/site-packages/django/core/cache/backends/redis.py", line 187, in get
    return self._cache.get(key, default)
  File "/Library/Frameworks/Python.framework/Versions/3.10/lib/python3.10/site-packages/django/core/cache/backends/redis.py", line 99, in get
    value = client.get(key)
  File "/Library/Frameworks/Python.framework/Versions/3.10/lib/python3.10/site-packages/redis/commands/core.py", line 1822, in get
    return self.execute_command("GET", name, keys=[name])
  File "/Library/Frameworks/Python.framework/Versions/3.10/lib/python3.10/site-packages/redis/client.py", line 559, in execute_command
    return self._execute_command(*args, **options)
  File "/Library/Frameworks/Python.framework/Versions/3.10/lib/python3.10/site-packages/redis/client.py", line 565, in _execute_command
    conn = self.connection or pool.get_connection(command_name, **options)
  File "/Library/Frameworks/Python.framework/Versions/3.10/lib/python3.10/site-packages/redis/connection.py", line 1422, in get_connection
    connection.connect()
  File "/Library/Frameworks/Python.framework/Versions/3.10/lib/python3.10/site-packages/redis/connection.py", line 363, in connect
    raise ConnectionError(self._error_message(e))
redis.exceptions.ConnectionError: Error 61 connecting to 127.0.0.1:1010. Connection refused.
"GET /api/products/product/ HTTP/1.1" 500 140352
Internal Server Error: /api/products/product/
Traceback (most recent call last):
  File "/Library/Frameworks/Python.framework/Versions/3.10/lib/python3.10/site-packages/redis/connection.py", line 357, in connect
    sock = self.retry.call_with_retry(
  File "/Library/Frameworks/Python.framework/Versions/3.10/lib/python3.10/site-packages/redis/retry.py", line 62, in call_with_retry
    return do()
  File "/Library/Frameworks/Python.framework/Versions/3.10/lib/python3.10/site-packages/redis/connection.py", line 358, in <lambda>
    lambda: self._connect(), lambda error: self.disconnect(error)
  File "/Library/Frameworks/Python.framework/Versions/3.10/lib/python3.10/site-packages/redis/connection.py", line 730, in _connect
    raise err
  File "/Library/Frameworks/Python.framework/Versions/3.10/lib/python3.10/site-packages/redis/connection.py", line 718, in _connect
    sock.connect(socket_address)
ConnectionRefusedError: [Errno 61] Connection refused

During handling of the above exception, another exception occurred:

Traceback (most recent call last):
  File "/Library/Frameworks/Python.framework/Versions/3.10/lib/python3.10/site-packages/django/core/handlers/exception.py", line 55, in inner
    response = get_response(request)
  File "/Library/Frameworks/Python.framework/Versions/3.10/lib/python3.10/site-packages/django/core/handlers/base.py", line 197, in _get_response
    response = wrapped_callback(request, *callback_args, **callback_kwargs)
  File "/Library/Frameworks/Python.framework/Versions/3.10/lib/python3.10/site-packages/django/views/decorators/csrf.py", line 65, in _view_wrapper
    return view_func(request, *args, **kwargs)
  File "/Library/Frameworks/Python.framework/Versions/3.10/lib/python3.10/site-packages/rest_framework/viewsets.py", line 124, in view
    return self.dispatch(request, *args, **kwargs)
  File "/Library/Frameworks/Python.framework/Versions/3.10/lib/python3.10/site-packages/rest_framework/views.py", line 509, in dispatch
    response = self.handle_exception(exc)
  File "/Library/Frameworks/Python.framework/Versions/3.10/lib/python3.10/site-packages/rest_framework/views.py", line 469, in handle_exception
    self.raise_uncaught_exception(exc)
  File "/Library/Frameworks/Python.framework/Versions/3.10/lib/python3.10/site-packages/rest_framework/views.py", line 480, in raise_uncaught_exception
    raise exc
  File "/Library/Frameworks/Python.framework/Versions/3.10/lib/python3.10/site-packages/rest_framework/views.py", line 506, in dispatch
    response = handler(request, *args, **kwargs)
  File "/Users/nursultantolegen/sales_trading_app/products/views.py", line 17, in list
    cached_data = cache.get(cache_key)
  File "/Library/Frameworks/Python.framework/Versions/3.10/lib/python3.10/site-packages/django/core/cache/backends/redis.py", line 187, in get
    return self._cache.get(key, default)
  File "/Library/Frameworks/Python.framework/Versions/3.10/lib/python3.10/site-packages/django/core/cache/backends/redis.py", line 99, in get
    value = client.get(key)
  File "/Library/Frameworks/Python.framework/Versions/3.10/lib/python3.10/site-packages/redis/commands/core.py", line 1822, in get
    return self.execute_command("GET", name, keys=[name])
  File "/Library/Frameworks/Python.framework/Versions/3.10/lib/python3.10/site-packages/redis/client.py", line 559, in execute_command
    return self._execute_command(*args, **options)
  File "/Library/Frameworks/Python.framework/Versions/3.10/lib/python3.10/site-packages/redis/client.py", line 565, in _execute_command
    conn = self.connection or pool.get_connection(command_name, **options)
  File "/Library/Frameworks/Python.framework/Versions/3.10/lib/python3.10/site-packages/redis/connection.py", line 1422, in get_connection
    connection.connect()
  File "/Library/Frameworks/Python.framework/Versions/3.10/lib/python3.10/site-packages/redis/connection.py", line 363, in connect
    raise ConnectionError(self._error_message(e))
redis.exceptions.ConnectionError: Error 61 connecting to 127.0.0.1:1010. Connection refused.
"GET /api/products/product/ HTTP/1.1" 500 140352
Internal Server Error: /api/products/product/
Traceback (most recent call last):
  File "/Library/Frameworks/Python.framework/Versions/3.10/lib/python3.10/site-packages/redis/connection.py", line 357, in connect
    sock = self.retry.call_with_retry(
  File "/Library/Frameworks/Python.framework/Versions/3.10/lib/python3.10/site-packages/redis/retry.py", line 62, in call_with_retry
    return do()
  File "/Library/Frameworks/Python.framework/Versions/3.10/lib/python3.10/site-packages/redis/connection.py", line 358, in <lambda>
    lambda: self._connect(), lambda error: self.disconnect(error)
  File "/Library/Frameworks/Python.framework/Versions/3.10/lib/python3.10/site-packages/redis/connection.py", line 730, in _connect
    raise err
  File "/Library/Frameworks/Python.framework/Versions/3.10/lib/python3.10/site-packages/redis/connection.py", line 718, in _connect
    sock.connect(socket_address)
ConnectionRefusedError: [Errno 61] Connection refused

During handling of the above exception, another exception occurred:

Traceback (most recent call last):
  File "/Library/Frameworks/Python.framework/Versions/3.10/lib/python3.10/site-packages/django/core/handlers/exception.py", line 55, in inner
    response = get_response(request)
  File "/Library/Frameworks/Python.framework/Versions/3.10/lib/python3.10/site-packages/django/core/handlers/base.py", line 197, in _get_response
    response = wrapped_callback(request, *callback_args, **callback_kwargs)
  File "/Library/Frameworks/Python.framework/Versions/3.10/lib/python3.10/site-packages/django/views/decorators/csrf.py", line 65, in _view_wrapper
    return view_func(request, *args, **kwargs)
  File "/Library/Frameworks/Python.framework/Versions/3.10/lib/python3.10/site-packages/rest_framework/viewsets.py", line 124, in view
    return self.dispatch(request, *args, **kwargs)
  File "/Library/Frameworks/Python.framework/Versions/3.10/lib/python3.10/site-packages/rest_framework/views.py", line 509, in dispatch
    response = self.handle_exception(exc)
  File "/Library/Frameworks/Python.framework/Versions/3.10/lib/python3.10/site-packages/rest_framework/views.py", line 469, in handle_exception
    self.raise_uncaught_exception(exc)
  File "/Library/Frameworks/Python.framework/Versions/3.10/lib/python3.10/site-packages/rest_framework/views.py", line 480, in raise_uncaught_exception
    raise exc
  File "/Library/Frameworks/Python.framework/Versions/3.10/lib/python3.10/site-packages/rest_framework/views.py", line 506, in dispatch
    response = handler(request, *args, **kwargs)
  File "/Users/nursultantolegen/sales_trading_app/products/views.py", line 17, in list
    cached_data = cache.get(cache_key)
  File "/Library/Frameworks/Python.framework/Versions/3.10/lib/python3.10/site-packages/django/core/cache/backends/redis.py", line 187, in get
    return self._cache.get(key, default)
  File "/Library/Frameworks/Python.framework/Versions/3.10/lib/python3.10/site-packages/django/core/cache/backends/redis.py", line 99, in get
    value = client.get(key)
  File "/Library/Frameworks/Python.framework/Versions/3.10/lib/python3.10/site-packages/redis/commands/core.py", line 1822, in get
    return self.execute_command("GET", name, keys=[name])
  File "/Library/Frameworks/Python.framework/Versions/3.10/lib/python3.10/site-packages/redis/client.py", line 559, in execute_command
    return self._execute_command(*args, **options)
  File "/Library/Frameworks/Python.framework/Versions/3.10/lib/python3.10/site-packages/redis/client.py", line 565, in _execute_command
    conn = self.connection or pool.get_connection(command_name, **options)
  File "/Library/Frameworks/Python.framework/Versions/3.10/lib/python3.10/site-packages/redis/connection.py", line 1422, in get_connection
    connection.connect()
  File "/Library/Frameworks/Python.framework/Versions/3.10/lib/python3.10/site-packages/redis/connection.py", line 363, in connect
    raise ConnectionError(self._error_message(e))
redis.exceptions.ConnectionError: Error 61 connecting to 127.0.0.1:1010. Connection refused.
"GET /api/products/product/ HTTP/1.1" 500 140352
Watching for file changes with StatReloader
Internal Server Error: /api/products/product/
Traceback (most recent call last):
  File "/Library/Frameworks/Python.framework/Versions/3.10/lib/python3.10/site-packages/redis/connection.py", line 357, in connect
    sock = self.retry.call_with_retry(
  File "/Library/Frameworks/Python.framework/Versions/3.10/lib/python3.10/site-packages/redis/retry.py", line 62, in call_with_retry
    return do()
  File "/Library/Frameworks/Python.framework/Versions/3.10/lib/python3.10/site-packages/redis/connection.py", line 358, in <lambda>
    lambda: self._connect(), lambda error: self.disconnect(error)
  File "/Library/Frameworks/Python.framework/Versions/3.10/lib/python3.10/site-packages/redis/connection.py", line 730, in _connect
    raise err
  File "/Library/Frameworks/Python.framework/Versions/3.10/lib/python3.10/site-packages/redis/connection.py", line 718, in _connect
    sock.connect(socket_address)
ConnectionRefusedError: [Errno 61] Connection refused

During handling of the above exception, another exception occurred:

Traceback (most recent call last):
  File "/Library/Frameworks/Python.framework/Versions/3.10/lib/python3.10/site-packages/django/core/handlers/exception.py", line 55, in inner
    response = get_response(request)
  File "/Library/Frameworks/Python.framework/Versions/3.10/lib/python3.10/site-packages/django/core/handlers/base.py", line 197, in _get_response
    response = wrapped_callback(request, *callback_args, **callback_kwargs)
  File "/Library/Frameworks/Python.framework/Versions/3.10/lib/python3.10/site-packages/django/views/decorators/csrf.py", line 65, in _view_wrapper
    return view_func(request, *args, **kwargs)
  File "/Library/Frameworks/Python.framework/Versions/3.10/lib/python3.10/site-packages/rest_framework/viewsets.py", line 124, in view
    return self.dispatch(request, *args, **kwargs)
  File "/Library/Frameworks/Python.framework/Versions/3.10/lib/python3.10/site-packages/rest_framework/views.py", line 509, in dispatch
    response = self.handle_exception(exc)
  File "/Library/Frameworks/Python.framework/Versions/3.10/lib/python3.10/site-packages/rest_framework/views.py", line 469, in handle_exception
    self.raise_uncaught_exception(exc)
  File "/Library/Frameworks/Python.framework/Versions/3.10/lib/python3.10/site-packages/rest_framework/views.py", line 480, in raise_uncaught_exception
    raise exc
  File "/Library/Frameworks/Python.framework/Versions/3.10/lib/python3.10/site-packages/rest_framework/views.py", line 506, in dispatch
    response = handler(request, *args, **kwargs)
  File "/Users/nursultantolegen/sales_trading_app/products/views.py", line 17, in list
    cached_data = cache.get(cache_key)
  File "/Library/Frameworks/Python.framework/Versions/3.10/lib/python3.10/site-packages/django/core/cache/backends/redis.py", line 187, in get
    return self._cache.get(key, default)
  File "/Library/Frameworks/Python.framework/Versions/3.10/lib/python3.10/site-packages/django/core/cache/backends/redis.py", line 99, in get
    value = client.get(key)
  File "/Library/Frameworks/Python.framework/Versions/3.10/lib/python3.10/site-packages/redis/commands/core.py", line 1822, in get
    return self.execute_command("GET", name, keys=[name])
  File "/Library/Frameworks/Python.framework/Versions/3.10/lib/python3.10/site-packages/redis/client.py", line 559, in execute_command
    return self._execute_command(*args, **options)
  File "/Library/Frameworks/Python.framework/Versions/3.10/lib/python3.10/site-packages/redis/client.py", line 565, in _execute_command
    conn = self.connection or pool.get_connection(command_name, **options)
  File "/Library/Frameworks/Python.framework/Versions/3.10/lib/python3.10/site-packages/redis/connection.py", line 1422, in get_connection
    connection.connect()
  File "/Library/Frameworks/Python.framework/Versions/3.10/lib/python3.10/site-packages/redis/connection.py", line 363, in connect
    raise ConnectionError(self._error_message(e))
redis.exceptions.ConnectionError: Error 61 connecting to 127.0.0.1:6379. Connection refused.
"GET /api/products/product/ HTTP/1.1" 500 140352
Internal Server Error: /api/products/product/
Traceback (most recent call last):
  File "/Library/Frameworks/Python.framework/Versions/3.10/lib/python3.10/site-packages/redis/connection.py", line 357, in connect
    sock = self.retry.call_with_retry(
  File "/Library/Frameworks/Python.framework/Versions/3.10/lib/python3.10/site-packages/redis/retry.py", line 62, in call_with_retry
    return do()
  File "/Library/Frameworks/Python.framework/Versions/3.10/lib/python3.10/site-packages/redis/connection.py", line 358, in <lambda>
    lambda: self._connect(), lambda error: self.disconnect(error)
  File "/Library/Frameworks/Python.framework/Versions/3.10/lib/python3.10/site-packages/redis/connection.py", line 730, in _connect
    raise err
  File "/Library/Frameworks/Python.framework/Versions/3.10/lib/python3.10/site-packages/redis/connection.py", line 718, in _connect
    sock.connect(socket_address)
ConnectionRefusedError: [Errno 61] Connection refused

During handling of the above exception, another exception occurred:

Traceback (most recent call last):
  File "/Library/Frameworks/Python.framework/Versions/3.10/lib/python3.10/site-packages/django/core/handlers/exception.py", line 55, in inner
    response = get_response(request)
  File "/Library/Frameworks/Python.framework/Versions/3.10/lib/python3.10/site-packages/django/core/handlers/base.py", line 197, in _get_response
    response = wrapped_callback(request, *callback_args, **callback_kwargs)
  File "/Library/Frameworks/Python.framework/Versions/3.10/lib/python3.10/site-packages/django/views/decorators/csrf.py", line 65, in _view_wrapper
    return view_func(request, *args, **kwargs)
  File "/Library/Frameworks/Python.framework/Versions/3.10/lib/python3.10/site-packages/rest_framework/viewsets.py", line 124, in view
    return self.dispatch(request, *args, **kwargs)
  File "/Library/Frameworks/Python.framework/Versions/3.10/lib/python3.10/site-packages/rest_framework/views.py", line 509, in dispatch
    response = self.handle_exception(exc)
  File "/Library/Frameworks/Python.framework/Versions/3.10/lib/python3.10/site-packages/rest_framework/views.py", line 469, in handle_exception
    self.raise_uncaught_exception(exc)
  File "/Library/Frameworks/Python.framework/Versions/3.10/lib/python3.10/site-packages/rest_framework/views.py", line 480, in raise_uncaught_exception
    raise exc
  File "/Library/Frameworks/Python.framework/Versions/3.10/lib/python3.10/site-packages/rest_framework/views.py", line 506, in dispatch
    response = handler(request, *args, **kwargs)
  File "/Users/nursultantolegen/sales_trading_app/products/views.py", line 17, in list
    cached_data = cache.get(cache_key)
  File "/Library/Frameworks/Python.framework/Versions/3.10/lib/python3.10/site-packages/django/core/cache/backends/redis.py", line 187, in get
    return self._cache.get(key, default)
  File "/Library/Frameworks/Python.framework/Versions/3.10/lib/python3.10/site-packages/django/core/cache/backends/redis.py", line 99, in get
    value = client.get(key)
  File "/Library/Frameworks/Python.framework/Versions/3.10/lib/python3.10/site-packages/redis/commands/core.py", line 1822, in get
    return self.execute_command("GET", name, keys=[name])
  File "/Library/Frameworks/Python.framework/Versions/3.10/lib/python3.10/site-packages/redis/client.py", line 559, in execute_command
    return self._execute_command(*args, **options)
  File "/Library/Frameworks/Python.framework/Versions/3.10/lib/python3.10/site-packages/redis/client.py", line 565, in _execute_command
    conn = self.connection or pool.get_connection(command_name, **options)
  File "/Library/Frameworks/Python.framework/Versions/3.10/lib/python3.10/site-packages/redis/connection.py", line 1422, in get_connection
    connection.connect()
  File "/Library/Frameworks/Python.framework/Versions/3.10/lib/python3.10/site-packages/redis/connection.py", line 363, in connect
    raise ConnectionError(self._error_message(e))
redis.exceptions.ConnectionError: Error 61 connecting to 127.0.0.1:6379. Connection refused.
"GET /api/products/product/ HTTP/1.1" 500 140352
Watching for file changes with StatReloader
Bad Request: /api/users/register/
"POST /api/users/register/ HTTP/1.1" 400 40
Unauthorized: /api/products/products/
"POST /api/products/products/ HTTP/1.1" 401 58
"GET /admin/ HTTP/1.1" 200 7603
Not Found: /
"GET / HTTP/1.1" 404 2747
Watching for file changes with StatReloader
/Users/nursultantolegen/sales_trading_app/products/urls.py changed, reloading.
Watching for file changes with StatReloader
Not Found: /
"GET / HTTP/1.1" 404 2747
Not Found: /profile/
"GET /profile/ HTTP/1.1" 404 2789
"GET /admin/ HTTP/1.1" 200 7603
Method Not Allowed: /api/users/register/
"GET /api/users/register/ HTTP/1.1" 405 8457
"GET /api/products/categories/?format=json HTTP/1.1" 200 2
"GET /api/products/categories/?format=json HTTP/1.1" 200 2
Internal Server Error: /api/products/
Traceback (most recent call last):
  File "/Library/Frameworks/Python.framework/Versions/3.10/lib/python3.10/site-packages/redis/connection.py", line 357, in connect
    sock = self.retry.call_with_retry(
  File "/Library/Frameworks/Python.framework/Versions/3.10/lib/python3.10/site-packages/redis/retry.py", line 62, in call_with_retry
    return do()
  File "/Library/Frameworks/Python.framework/Versions/3.10/lib/python3.10/site-packages/redis/connection.py", line 358, in <lambda>
    lambda: self._connect(), lambda error: self.disconnect(error)
  File "/Library/Frameworks/Python.framework/Versions/3.10/lib/python3.10/site-packages/redis/connection.py", line 730, in _connect
    raise err
  File "/Library/Frameworks/Python.framework/Versions/3.10/lib/python3.10/site-packages/redis/connection.py", line 718, in _connect
    sock.connect(socket_address)
ConnectionRefusedError: [Errno 61] Connection refused

During handling of the above exception, another exception occurred:

Traceback (most recent call last):
  File "/Library/Frameworks/Python.framework/Versions/3.10/lib/python3.10/site-packages/django/core/handlers/exception.py", line 55, in inner
    response = get_response(request)
  File "/Library/Frameworks/Python.framework/Versions/3.10/lib/python3.10/site-packages/django/core/handlers/base.py", line 197, in _get_response
    response = wrapped_callback(request, *callback_args, **callback_kwargs)
  File "/Library/Frameworks/Python.framework/Versions/3.10/lib/python3.10/site-packages/django/views/decorators/csrf.py", line 65, in _view_wrapper
    return view_func(request, *args, **kwargs)
  File "/Library/Frameworks/Python.framework/Versions/3.10/lib/python3.10/site-packages/rest_framework/viewsets.py", line 124, in view
    return self.dispatch(request, *args, **kwargs)
  File "/Library/Frameworks/Python.framework/Versions/3.10/lib/python3.10/site-packages/rest_framework/views.py", line 509, in dispatch
    response = self.handle_exception(exc)
  File "/Library/Frameworks/Python.framework/Versions/3.10/lib/python3.10/site-packages/rest_framework/views.py", line 469, in handle_exception
    self.raise_uncaught_exception(exc)
  File "/Library/Frameworks/Python.framework/Versions/3.10/lib/python3.10/site-packages/rest_framework/views.py", line 480, in raise_uncaught_exception
    raise exc
  File "/Library/Frameworks/Python.framework/Versions/3.10/lib/python3.10/site-packages/rest_framework/views.py", line 506, in dispatch
    response = handler(request, *args, **kwargs)
  File "/Users/nursultantolegen/sales_trading_app/products/views.py", line 17, in list
    cached_data = cache.get(cache_key)
  File "/Library/Frameworks/Python.framework/Versions/3.10/lib/python3.10/site-packages/django/core/cache/backends/redis.py", line 187, in get
    return self._cache.get(key, default)
  File "/Library/Frameworks/Python.framework/Versions/3.10/lib/python3.10/site-packages/django/core/cache/backends/redis.py", line 99, in get
    value = client.get(key)
  File "/Library/Frameworks/Python.framework/Versions/3.10/lib/python3.10/site-packages/redis/commands/core.py", line 1822, in get
    return self.execute_command("GET", name, keys=[name])
  File "/Library/Frameworks/Python.framework/Versions/3.10/lib/python3.10/site-packages/redis/client.py", line 559, in execute_command
    return self._execute_command(*args, **options)
  File "/Library/Frameworks/Python.framework/Versions/3.10/lib/python3.10/site-packages/redis/client.py", line 565, in _execute_command
    conn = self.connection or pool.get_connection(command_name, **options)
  File "/Library/Frameworks/Python.framework/Versions/3.10/lib/python3.10/site-packages/redis/connection.py", line 1422, in get_connection
    connection.connect()
  File "/Library/Frameworks/Python.framework/Versions/3.10/lib/python3.10/site-packages/redis/connection.py", line 363, in connect
    raise ConnectionError(self._error_message(e))
redis.exceptions.ConnectionError: Error 61 connecting to 127.0.0.1:6379. Connection refused.
"GET /api/products/ HTTP/1.1" 500 140224
Not Found: /api/products/product/
"GET /api/products/product/ HTTP/1.1" 404 3497
Not Found: /api/products/post/
"GET /api/products/post/ HTTP/1.1" 404 3488
Internal Server Error: /api/products/
Traceback (most recent call last):
  File "/Library/Frameworks/Python.framework/Versions/3.10/lib/python3.10/site-packages/redis/connection.py", line 357, in connect
    sock = self.retry.call_with_retry(
  File "/Library/Frameworks/Python.framework/Versions/3.10/lib/python3.10/site-packages/redis/retry.py", line 62, in call_with_retry
    return do()
  File "/Library/Frameworks/Python.framework/Versions/3.10/lib/python3.10/site-packages/redis/connection.py", line 358, in <lambda>
    lambda: self._connect(), lambda error: self.disconnect(error)
  File "/Library/Frameworks/Python.framework/Versions/3.10/lib/python3.10/site-packages/redis/connection.py", line 730, in _connect
    raise err
  File "/Library/Frameworks/Python.framework/Versions/3.10/lib/python3.10/site-packages/redis/connection.py", line 718, in _connect
    sock.connect(socket_address)
ConnectionRefusedError: [Errno 61] Connection refused

During handling of the above exception, another exception occurred:

Traceback (most recent call last):
  File "/Library/Frameworks/Python.framework/Versions/3.10/lib/python3.10/site-packages/django/core/handlers/exception.py", line 55, in inner
    response = get_response(request)
  File "/Library/Frameworks/Python.framework/Versions/3.10/lib/python3.10/site-packages/django/core/handlers/base.py", line 197, in _get_response
    response = wrapped_callback(request, *callback_args, **callback_kwargs)
  File "/Library/Frameworks/Python.framework/Versions/3.10/lib/python3.10/site-packages/django/views/decorators/csrf.py", line 65, in _view_wrapper
    return view_func(request, *args, **kwargs)
  File "/Library/Frameworks/Python.framework/Versions/3.10/lib/python3.10/site-packages/rest_framework/viewsets.py", line 124, in view
    return self.dispatch(request, *args, **kwargs)
  File "/Library/Frameworks/Python.framework/Versions/3.10/lib/python3.10/site-packages/rest_framework/views.py", line 509, in dispatch
    response = self.handle_exception(exc)
  File "/Library/Frameworks/Python.framework/Versions/3.10/lib/python3.10/site-packages/rest_framework/views.py", line 469, in handle_exception
    self.raise_uncaught_exception(exc)
  File "/Library/Frameworks/Python.framework/Versions/3.10/lib/python3.10/site-packages/rest_framework/views.py", line 480, in raise_uncaught_exception
    raise exc
  File "/Library/Frameworks/Python.framework/Versions/3.10/lib/python3.10/site-packages/rest_framework/views.py", line 506, in dispatch
    response = handler(request, *args, **kwargs)
  File "/Users/nursultantolegen/sales_trading_app/products/views.py", line 17, in list
    cached_data = cache.get(cache_key)
  File "/Library/Frameworks/Python.framework/Versions/3.10/lib/python3.10/site-packages/django/core/cache/backends/redis.py", line 187, in get
    return self._cache.get(key, default)
  File "/Library/Frameworks/Python.framework/Versions/3.10/lib/python3.10/site-packages/django/core/cache/backends/redis.py", line 99, in get
    value = client.get(key)
  File "/Library/Frameworks/Python.framework/Versions/3.10/lib/python3.10/site-packages/redis/commands/core.py", line 1822, in get
    return self.execute_command("GET", name, keys=[name])
  File "/Library/Frameworks/Python.framework/Versions/3.10/lib/python3.10/site-packages/redis/client.py", line 559, in execute_command
    return self._execute_command(*args, **options)
  File "/Library/Frameworks/Python.framework/Versions/3.10/lib/python3.10/site-packages/redis/client.py", line 565, in _execute_command
    conn = self.connection or pool.get_connection(command_name, **options)
  File "/Library/Frameworks/Python.framework/Versions/3.10/lib/python3.10/site-packages/redis/connection.py", line 1422, in get_connection
    connection.connect()
  File "/Library/Frameworks/Python.framework/Versions/3.10/lib/python3.10/site-packages/redis/connection.py", line 363, in connect
    raise ConnectionError(self._error_message(e))
redis.exceptions.ConnectionError: Error 61 connecting to 127.0.0.1:6379. Connection refused.
"GET /api/products/ HTTP/1.1" 500 140224
"GET /api/products/categories/?format=json HTTP/1.1" 200 2
Unauthorized: /api/sales/orders/
"GET /api/sales/orders/ HTTP/1.1" 401 5170
Unauthorized: /api/sales/orders/
"GET /api/sales/orders/?format=json HTTP/1.1" 401 58
Method Not Allowed: /api/users/register/
"GET /api/users/register/ HTTP/1.1" 405 8457
